2025-03-03 23:49:41,059 INFO    MainThread:901454 [wandb_init.py:setup_run_log_directory():647] Logging user logs to /home/kanchan/Downloads/Courses/DL(DA6401)/CS23S025-Assignment-1_DA6401-DL/wandb/run-20250303_234941-hbp8bq2b/logs/debug.log
2025-03-03 23:49:41,059 INFO    MainThread:901454 [wandb_init.py:setup_run_log_directory():648] Logging internal logs to /home/kanchan/Downloads/Courses/DL(DA6401)/CS23S025-Assignment-1_DA6401-DL/wandb/run-20250303_234941-hbp8bq2b/logs/debug-internal.log
2025-03-03 23:49:41,059 INFO    MainThread:901454 [wandb_init.py:init():761] calling init triggers
2025-03-03 23:49:41,060 INFO    MainThread:901454 [wandb_init.py:init():766] wandb.init called with sweep_config: {}
config: {'_wandb': {}}
2025-03-03 23:49:41,060 INFO    MainThread:901454 [wandb_init.py:init():784] starting backend
2025-03-03 23:49:41,060 INFO    MainThread:901454 [wandb_init.py:init():788] sending inform_init request
2025-03-03 23:49:41,061 INFO    MainThread:901454 [backend.py:_multiprocessing_setup():97] multiprocessing start_methods=fork,spawn,forkserver, using: spawn
2025-03-03 23:49:41,061 INFO    MainThread:901454 [wandb_init.py:init():803] backend started and connected
2025-03-03 23:49:41,062 INFO    MainThread:901454 [wandb_run.py:_label_probe_notebook():1204] probe notebook
2025-03-03 23:49:41,063 INFO    MainThread:901454 [wandb_init.py:init():896] updated telemetry
2025-03-03 23:49:41,066 INFO    MainThread:901454 [wandb_init.py:init():920] communicating run to backend with 90.0 second timeout
2025-03-03 23:49:41,505 WARNING MsgRouterThr:901454 [router.py:message_loop():77] message_loop has been closed
Traceback (most recent call last):
  File "/home/kanchan/Downloads/Courses/DL(DA6401)/CS23S025-Assignment-1_DA6401-DL/DLenv/lib/python3.12/site-packages/wandb/sdk/lib/sock_client.py", line 258, in _read_packet_bytes
    data = self._sock.recv(self._bufsize)
           ^^^^^^^^^^^^^^^^^^^^^^^^^^^^^^
BlockingIOError: [Errno 11] Resource temporarily unavailable

The above exception was the direct cause of the following exception:

Traceback (most recent call last):
  File "/home/kanchan/Downloads/Courses/DL(DA6401)/CS23S025-Assignment-1_DA6401-DL/DLenv/lib/python3.12/site-packages/wandb/sdk/interface/router_sock.py", line 28, in _read_message
    resp = self._sock_client.read_server_response(timeout=1)
           ^^^^^^^^^^^^^^^^^^^^^^^^^^^^^^^^^^^^^^^^^^^^^^^^^
  File "/home/kanchan/Downloads/Courses/DL(DA6401)/CS23S025-Assignment-1_DA6401-DL/DLenv/lib/python3.12/site-packages/wandb/sdk/lib/sock_client.py", line 285, in read_server_response
    data = self._read_packet_bytes(timeout=timeout)
           ^^^^^^^^^^^^^^^^^^^^^^^^^^^^^^^^^^^^^^^^
  File "/home/kanchan/Downloads/Courses/DL(DA6401)/CS23S025-Assignment-1_DA6401-DL/DLenv/lib/python3.12/site-packages/wandb/sdk/lib/sock_client.py", line 262, in _read_packet_bytes
    raise SockClientClosedError from e
wandb.sdk.lib.sock_client.SockClientClosedError

The above exception was the direct cause of the following exception:

Traceback (most recent call last):
  File "/home/kanchan/Downloads/Courses/DL(DA6401)/CS23S025-Assignment-1_DA6401-DL/DLenv/lib/python3.12/site-packages/wandb/sdk/interface/router.py", line 70, in message_loop
    msg = self._read_message()
          ^^^^^^^^^^^^^^^^^^^^
  File "/home/kanchan/Downloads/Courses/DL(DA6401)/CS23S025-Assignment-1_DA6401-DL/DLenv/lib/python3.12/site-packages/wandb/sdk/interface/router_sock.py", line 30, in _read_message
    raise MessageRouterClosedError from e
wandb.sdk.interface.router.MessageRouterClosedError
2025-03-03 23:49:41,506 INFO    MainThread:901454 [wandb_init.py:init():995] starting run threads in backend
2025-03-03 23:49:41,506 INFO    MsgRouterThr:901454 [mailbox.py:close():115] Closing mailbox, abandoning 1 handles.
2025-03-03 23:49:41,508 WARNING MsgRouterThr:901454 [router.py:message_loop():77] message_loop has been closed
Traceback (most recent call last):
  File "/home/kanchan/Downloads/Courses/DL(DA6401)/CS23S025-Assignment-1_DA6401-DL/DLenv/lib/python3.12/site-packages/wandb/sdk/lib/sock_client.py", line 258, in _read_packet_bytes
    data = self._sock.recv(self._bufsize)
           ^^^^^^^^^^^^^^^^^^^^^^^^^^^^^^
BlockingIOError: [Errno 11] Resource temporarily unavailable

The above exception was the direct cause of the following exception:

Traceback (most recent call last):
  File "/home/kanchan/Downloads/Courses/DL(DA6401)/CS23S025-Assignment-1_DA6401-DL/DLenv/lib/python3.12/site-packages/wandb/sdk/interface/router_sock.py", line 28, in _read_message
    resp = self._sock_client.read_server_response(timeout=1)
           ^^^^^^^^^^^^^^^^^^^^^^^^^^^^^^^^^^^^^^^^^^^^^^^^^
  File "/home/kanchan/Downloads/Courses/DL(DA6401)/CS23S025-Assignment-1_DA6401-DL/DLenv/lib/python3.12/site-packages/wandb/sdk/lib/sock_client.py", line 285, in read_server_response
    data = self._read_packet_bytes(timeout=timeout)
           ^^^^^^^^^^^^^^^^^^^^^^^^^^^^^^^^^^^^^^^^
  File "/home/kanchan/Downloads/Courses/DL(DA6401)/CS23S025-Assignment-1_DA6401-DL/DLenv/lib/python3.12/site-packages/wandb/sdk/lib/sock_client.py", line 262, in _read_packet_bytes
    raise SockClientClosedError from e
wandb.sdk.lib.sock_client.SockClientClosedError

The above exception was the direct cause of the following exception:

Traceback (most recent call last):
  File "/home/kanchan/Downloads/Courses/DL(DA6401)/CS23S025-Assignment-1_DA6401-DL/DLenv/lib/python3.12/site-packages/wandb/sdk/interface/router.py", line 70, in message_loop
    msg = self._read_message()
          ^^^^^^^^^^^^^^^^^^^^
  File "/home/kanchan/Downloads/Courses/DL(DA6401)/CS23S025-Assignment-1_DA6401-DL/DLenv/lib/python3.12/site-packages/wandb/sdk/interface/router_sock.py", line 30, in _read_message
    raise MessageRouterClosedError from e
wandb.sdk.interface.router.MessageRouterClosedError
2025-03-03 23:49:41,508 INFO    MsgRouterThr:901454 [mailbox.py:close():115] Closing mailbox, abandoning 6 handles.
2025-03-03 23:50:11,566 INFO    MainThread:901454 [wandb_run.py:_console_start():2377] atexit reg
2025-03-03 23:50:11,566 INFO    MainThread:901454 [wandb_run.py:_redirect():2227] redirect: wrap_raw
2025-03-03 23:50:11,566 INFO    MainThread:901454 [wandb_run.py:_redirect():2292] Wrapping output streams.
2025-03-03 23:50:11,566 INFO    MainThread:901454 [wandb_run.py:_redirect():2317] Redirects installed.
2025-03-03 23:50:11,567 INFO    MainThread:901454 [wandb_init.py:init():1037] run started, returning control to user process
2025-03-03 23:50:31,566 WARNING MsgRouterThr:901454 [router.py:message_loop():77] message_loop has been closed
Traceback (most recent call last):
  File "/home/kanchan/Downloads/Courses/DL(DA6401)/CS23S025-Assignment-1_DA6401-DL/DLenv/lib/python3.12/site-packages/wandb/sdk/lib/sock_client.py", line 258, in _read_packet_bytes
    data = self._sock.recv(self._bufsize)
           ^^^^^^^^^^^^^^^^^^^^^^^^^^^^^^
BlockingIOError: [Errno 11] Resource temporarily unavailable

The above exception was the direct cause of the following exception:

Traceback (most recent call last):
  File "/home/kanchan/Downloads/Courses/DL(DA6401)/CS23S025-Assignment-1_DA6401-DL/DLenv/lib/python3.12/site-packages/wandb/sdk/interface/router_sock.py", line 28, in _read_message
    resp = self._sock_client.read_server_response(timeout=1)
           ^^^^^^^^^^^^^^^^^^^^^^^^^^^^^^^^^^^^^^^^^^^^^^^^^
  File "/home/kanchan/Downloads/Courses/DL(DA6401)/CS23S025-Assignment-1_DA6401-DL/DLenv/lib/python3.12/site-packages/wandb/sdk/lib/sock_client.py", line 285, in read_server_response
    data = self._read_packet_bytes(timeout=timeout)
           ^^^^^^^^^^^^^^^^^^^^^^^^^^^^^^^^^^^^^^^^
  File "/home/kanchan/Downloads/Courses/DL(DA6401)/CS23S025-Assignment-1_DA6401-DL/DLenv/lib/python3.12/site-packages/wandb/sdk/lib/sock_client.py", line 262, in _read_packet_bytes
    raise SockClientClosedError from e
wandb.sdk.lib.sock_client.SockClientClosedError

The above exception was the direct cause of the following exception:

Traceback (most recent call last):
  File "/home/kanchan/Downloads/Courses/DL(DA6401)/CS23S025-Assignment-1_DA6401-DL/DLenv/lib/python3.12/site-packages/wandb/sdk/interface/router.py", line 70, in message_loop
    msg = self._read_message()
          ^^^^^^^^^^^^^^^^^^^^
  File "/home/kanchan/Downloads/Courses/DL(DA6401)/CS23S025-Assignment-1_DA6401-DL/DLenv/lib/python3.12/site-packages/wandb/sdk/interface/router_sock.py", line 30, in _read_message
    raise MessageRouterClosedError from e
wandb.sdk.interface.router.MessageRouterClosedError
2025-03-03 23:50:31,567 INFO    MsgRouterThr:901454 [mailbox.py:close():115] Closing mailbox, abandoning 4 handles.
